Workbook

Sheet جرد ١٥ فبراير ٢٠٢٥
B3: مجموعة عمل الجرد مكونة من
A4: 1 | B4: الاسم
A5: 2 | B5: Hany G
A6: 3 | B6: Sony
A7: 4
A10: الكتب | C10: الرصيد الدفتري | D10: الجرد الفعلي 2025/2/15 | E10: فرق المخزون | F10: ملاحظات
A11: 1 | B11: النص الاساسى | C11: 400 | D11: 400 | E11: =D11-C11 -> 0
A12: 2 | B12: إنه يعمل - كيف ولماذا | C12: 260 | D12: 260 | E12: =D12-C12 -> 0
A13: 3 | B13: دليل العمل بالخطوات | C13: 230 | D13: 230 | E13: =D13-C13 -> 0
A14: 4 | B14: كتاب لليوم فقط | C14: 85 | D14: 103 | E14: =D14-C14 -> 18
A15: 5 | B15: الدليل التمهيدى | C15: 567 | D15: 567 | E15: =D15-C15 -> 0
A16: 6 | B16: روح تقاليدنا | C16: 183 | D16: 183 | E16: =D16-C16 -> 0
A17: 7 | B17: living clean | C17: 444 | D17: 444 | E17: =D17-C17 -> 0
A18: 8 | B18: النص الاساسى (جيب) | C18: 821 | D18: 812 | E18: =D18-C18 -> -9
A19: 9 | B19: إنة يعمل - كيف ولماذا (جيب) | C19: 0 | E19: =D19-C19 -> 0
A20: 10 | B20: دليل العمل بالخطوات (جيب) | C20: 0 | E20: =D20-C20 -> 0
A21: 11 | B21: كتاب لليوم فقط (جيب) | C21: 0 | E21: =D21-C21 -> 0
A22: 12 | B22: النص الاساسى (تذكاري) | C22: 0 | E22: =D22-C22 -> 0
A23: 13 | B23: أنة يعمل - كيف ولماذا (تذكاري) | C23: 14 | D23: 4 | E23: =D23-C23 -> -10
A24: 14 | B24: دليل عمل الخطوات (تذكاري) | C24: 9 | D24: 9 | E24: =D24-C24 -> 0
A25: 15 | B25: كتاب لليوم فقط (تذكاري) | C25: 0 | E25: =D25-C25 -> 0
A26: الكتيبات (IP)
A27: 1 | B27: للعضو الجديد | C27: 298 | D27: 300 | E27: =D27-C27 -> 2
A28: 2 | B28: هل انا مدمن | C28: 378 | D28: 374 | E28: =D28-C28 -> -4
A29: 3 | B29: مرحبا بك فى زمالة م.م. | C29: 491 | D29: 499 | E29: =D29-C29 -> 8
A30: 4 | B30: لليوم فقط | C30: 2986 | D30: 2998 | E30: =D30-C30 -> 12
A31: 5 | B31: التوجية | C31: 300 | D31: 300 | E31: =D31-C31 -> 0
A32: 6 | B32: نظرة أخرى | C32: 2901 | D32: 2899 | E32: =D32-C32 -> -2
A33: 7 | B33: التعافى والانتكاس | C33: 1668 | D33: 1670 | E33: =D33-C33 -> 2
A34: 8 | B34: تقبل الذات | C34: 1617 | D34: 1617 | E34: =D34-C34 -> 0
A35: 9 | B35: مثلث الهاجس الذاتي | C35: 382 | D35: 387 | E35: =D35-C35 -> 5
A36: 10 | B36: مقدمة لاجتماعات زمالة م.م | C36: 0 | D36: 0 | E36: =D36-C36 -> 0
A37: 11 | B37: من - ماذا - كيف ولماذا | C37: 1054 | D37: 1054 | E37: =D37-C37 -> 0
A38: 12 | B38: تجربة مدمن مع التقبل والإيمان والالتزام | C38: 1415 | D38: 1415 | E38: =D38-C38 -> 0
... A51: 25 | B51: امكانية الوصول لذوي الاحتيجات | C51: 500 | D51: 500 | E51: =D51-C51 -> 0
A52: الشيبات Chips
A53: 1 | B53: Welcome / White | C53: 0 | E53: =D53-C53 -> 0
A54: 2 | B54: 30 Days / Orange | C54: 471 | D54: 471 | E54: =D54-C54 -> 0
A55: 3 | B55: 60 Days / Green | C55: 408 | D55: 408 | E55: =D55-C55 -> 0
A56: 4 | B56: 90 Days / Red | C56: 115 | D56: 116 | E56: =D56-C56 -> 1
...

Sheet جرد ١٣ أغسطس ٢٠٢٥ مع الملاحظات
B2: مجموعة عمل الجرد مكونة من
B3: الاسم | C3: المنصب الخدمي
A4: 1 | B4: وليد | C4: امين صندوق الإقليم
A5: 2 | B5: كريم | C5: رئيس لجنة الادبيات
A6: 3 | B6: رامي | C6: شمال شرق RCM
A7: 4 | B7: سوني | C7: امين مخزن
A9: الكتب | C9: الرصيد الدفتري | D9: الجرد الفعلي 2025/8/13 | E9: فرق المخزون | F9: ملاحظات
A10: 1 | B10: النص الاساسى | C10: 20 | D10: 20 | E10: =D10-C10 -> 0
A11: 2 | B11: إنه يعمل - كيف ولماذا | C11: 90 | D11: 90 | E11: =D11-C11 -> 0
A12: 3 | B12: دليل العمل بالخطوات | C12: 60 | D12: 60 | E12: =D12-C12 -> 0
A13: 4 | B13: كتاب لليوم فقط | C13: 0 | D13: 0 | E13: =D13-C13 -> 0
A14: 5 | B14: الدليل التمهيدى | C14: 557 | D14: 557 | E14: =D14-C14 -> 0
A15: 6 | B15: روح تقاليدنا | C15: 73 | D15: 73 | E15: =D15-C15 -> 0
A16: 7 | B16: living clean | C16: 334 | D16: 334 | E16: =D16-C16 -> 0
A17: 8 | B17: النص الاساسى (جيب) | C17: 662 | D17: 662 | E17: =D17-C17 -> 0
A18: 9 | B18: إنة يعمل - كيف ولماذا (جيب) | C18: 0 | E18: =D18-C18 -> 0
A19: 10 | B19: دليل العمل بالخطوات (جيب) | C19: 0 | E19: =D19-C19 -> 0
A20: 11 | B20: كتاب لليوم فقط (جيب) | C20: 0 | E20: =D20-C20 -> 0
A21: 12 | B21: النص الاساسى (تذكاري) | C21: 0 | E21: =D21-C21 -> 0
A22: 13 | B22: أنة يعمل - كيف ولماذا (تذكاري) | C22: 0 | D22: 4 | E22: =D22-C22 -> 4 | F22: العدد مظبو ط تم تعديل الاعداد حسب نوع الكتباب
A23: 14 | B23: دليل عمل الخطوات (تذكاري) | C23: 13 | D23: 9 | E23: =D23-C23 -> -4
A24: 15 | B24: كتاب لليوم فقط (تذكاري) | C24: 0 | E24: =D24-C24 -> 0
A25: الكتيبات (IP)
A26: 1 | B26: للعضو الجديد | C26: 48 | D26: 48 | E26: =D26-C26 -> 0
A27: 2 | B27: هل انا مدمن | C27: 0 | E27: =D27-C27 -> 0
A28: 3 | B28: مرحبا بك فى زمالة م.م. | C28: 149 | D28: 150 | E28: =D28-C28 -> 1
A29: 4 | B29: لليوم فقط | C29: 2948 | D29: 2927 | E29: =D29-C29 -> -21 | F29: فرق جرد ١٥ فبراير ٢٠٢٥ ليس عليه حركة و تم تعديل العدد
A30: 5 | B30: التوجية | C30: 0 | E30: =D30-C30 -> 0
A31: 6 | B31: نظرة أخرى | C31: 2799 | D31: 2799 | E31: =D31-C31 -> 0
A32: 7 | B32: التعافى والانتكاس | C32: 1670 | D32: 1668 | E32: =D32-C32 -> -2 | F32: فرق جرد ١٥ فبراير ٢٠٢٥ ليس عليه حركة و تم تعديل العدد
A33: 8 | B33: تقبل الذات | C33: 1617 | D33: 1617 | E33: =D33-C33 -> 0
A34: 9 | B34: مثلث الهاجس الذاتي | C34: 387 | D34: 387 | E34: =D34-C34 -> 0
A35: 10 | B35: مقدمة لاجتماعات زمالة م.م | C35: 0 | E35: =D35-C35 -> 0
A36: 11 | B36: من - ماذا - كيف ولماذا | C36: 1054 | D36: 1054 | E36: =D36-C36 -> 0
A37: 12 | B37: تجربة مدمن مع التقبل والإيمان والالتزام | C37: 1415 | D37: 1415 | E37: =D37-C37 -> 0
A38: 13 | B38: البقاء ممتنعا في الخارج | C38: 1900 | D38: 1900 | E38: =D38-C38 -> 0
A39: 14 | B39: رسالة لمن هم بالمصحات | C39: 655 | D39: 655 | E39: =D39-C39 -> 0
A40: 15 | B40: التواصل الاجتماعى | C40: 300 | D40: 300 | E40: =D40-C40 -> 0
A41: 16 | B41: الخدم الموثوق بهم | C41: 500 | D41: 500 | E41: =D41-C41 -> 0
A42: 17 | B42: الامور المالية | C42: 450 | D42: 450 | E42: =D42-C42 -> 0
...

Sheet العهدة الحالية
A3: الكتب | C3: رصيد البداية 12 -6- 2026 | D3: إجمالي الصادر | E3: إجمالي الوارد | F3: الرصيد الحالي | G3: سعر البيع | H3: مجموع المخزون / جنيه مصري | I3: متوسط الإستهلاك الشهري | J3: الاستهلاك السنوي للأدبيات الإنجليزية | K3: كمية تكفي 4 شهور | L3: الفرق عن الحد الأدني
A4: 1 | B4: النص الاساسى | C4: 255 | D4: ='الصادر بعد الجرد'!Y4 -> 150 | E4: ='الوارد بعد الجرد'!AC4 -> 100 | F4: =C4-D4+E4 -> 205 | G4: 75 | H4: =G4*F4 -> 15375 | I4: 213 | K4: =I4*4 -> 852 | L4: =F4-K4 -> -647
A5: 2 | B5: إنه يعمل - كيف ولماذا | C5: 355 | D5: ='الصادر بعد الجرد'!Y5 -> 50 | E5: ='الوارد بعد الجرد'!AC5 -> 0 | F5: =C5-D5+E5 -> 305 | G5: 160 | H5: =G5*F5 -> 48800 | I5: 88 | K5: =I5*4 -> 352 | L5: =F5-K5 -> -47
A6: 3 | B6: دليل العمل بالخطوات | C6: 100 | D6: ='الصادر بعد الجرد'!Y6 -> 150 | E6: ='الوارد بعد الجرد'!AC6 -> 150 | F6: =C6-D6+E6 -> 100 | G6: 150 | H6: =G6*F6 -> 15000 | I6: 82 | K6: =I6*4 -> 328 | L6: =F6-K6 -> -228
A7: 4 | B7: كتاب لليوم فقط | C7: 525 | D7: ='الصادر بعد الجرد'!Y7 -> 40 | E7: ='الوارد بعد الجرد'!AC7 -> 0 | F7: =C7-D7+E7 -> 485 | G7: 100 | H7: =G7*F7 -> 48500 | K7: =I7*4 -> 0 | L7: =F7-K7 -> 485
A8: 5 | B8: الدليل التمهيدى | C8: 377 | D8: ='الصادر بعد الجرد'!Y8 -> 0 | E8: ='الوارد بعد الجرد'!AC8 -> 0 | F8: =C8-D8+E8 -> 377 | G8: 55 | H8: =G8*F8 -> 20735 | I8: 62 | K8: =I8*4 -> 248 | L8: =F8-K8 -> 129
A9: 6 | B9: روح تقاليدنا | C9: 907 | D9: ='الصادر بعد الجرد'!Y9 -> 40 | E9: ='الوارد بعد الجرد'!AC9 -> 0 | F9: =C9-D9+E9 -> 867 | G9: 130 | H9: =G9*F9 -> 112710 | K9: =I9*4 -> 0 | L9: =F9-K9 -> 867
A10: 7 | B10: living clean | C10: 940 | D10: ='الصادر بعد الجرد'!Y10 -> 60 | E10: ='الوارد بعد الجرد'!AC10 -> 0 | F10: =C10-D10+E10 -> 880 | G10: 85 | H10: =G10*F10 -> 74800 | K10: =I10*4 -> 0 | L10: =F10-K10 -> 880
A11: 8 | B11: النص الاساسى (جيب) | D11: ='الصادر بعد الجرد'!Y11 -> 0 | E11: ='الوارد بعد الجرد'!AC11 -> 0 | F11: =C11-D11+E11 -> 0 | G11: 25 | H11: =G11*F11 -> 0 | I11: 12 | K11: =I11*4 -> 48 | L11: =F11-K11 -> -48
A12: 9 | B12: إنة يعمل - كيف ولماذا (جيب) | D12: ='الصادر بعد الجرد'!Y12 -> 0 | E12: ='الوارد بعد الجرد'!AC12 -> 0 | F12: =C12-D12+E12 -> 0 | H12: =G12*F12 -> 0 | K12: =I12*4 -> 0 | L12: =F12-K12 -> 0
A13: 10 | B13: دليل العمل بالخطوات (جيب) | D13: ='الصادر بعد الجرد'!Y13 -> 0 | E13: ='الوارد بعد الجرد'!AC13 -> 0 | F13: =C13-D13+E13 -> 0 | H13: =G13*F13 -> 0 | K13: =I13*4 -> 0 | L13: =F13-K13 -> 0
A14: 11 | B14: كتاب لليوم فقط (جيب) | D14: ='الصادر بعد الجرد'!Y14 -> 0 | E14: ='الوارد بعد الجرد'!AC14 -> 0 | F14: =C14-D14+E14 -> 0 | H14: =G14*F14 -> 0 | K14: =I14*4 -> 0 | L14: =F14-K14 -> 0
A15: 12 | B15: النص الاساسى (تذكاري) | D15: ='الصادر بعد الجرد'!Y15 -> 0 | E15: ='الوارد بعد الجرد'!AC15 -> 0 | F15: =C15-D15+E15 -> 0 | G15: 150 | H15: =G15*F15 -> 0 | K15: =I15*4 -> 0 | L15: =F15-K15 -> 0
A16: 13 | B16: أنة يعمل - كيف ولماذا (تذكاري) | C16: 4 | D16: ='الصادر بعد الجرد'!Y16 -> 0 | E16: ='الوارد بعد الجرد'!AC16 -> 0 | F16: =C16-D16+E16 -> 4 | G16: 250 | H16: =G16*F16 -> 1000 | K16: =I16*4 -> 0 | L16: =F16-K16 -> 4
A17: 14 | B17: دليل عمل الخطوات (تذكاري) | C17: 4 | D17: ='الصادر بعد الجرد'!Y17 -> 0 | E17: ='الوارد بعد الجرد'!AC17 -> 0 | F17: =C17-D17+E17 -> 4 | G17: 240 | H17: =G17*F17 -> 960 | K17: =I17*4 -> 0 | L17: =F17-K17 -> 4
A18: 15 | B18: كتاب لليوم فقط (تذكاري) | D18: ='الصادر بعد الجرد'!Y18 -> 0 | E18: ='الوارد بعد الجرد'!AC18 -> 0 | F18: =C18-D18+E18 -> 0 | G18: 260 | H18: =G18*F18 -> 0 | K18: =I18*4 -> 0 | L18: =F18-K18 -> 0
B19: الكتيبات (IP)
A20: 1 | B20: للعضو الجديد | C20: 1248 | D20: ='الصادر بعد الجرد'!Y20 -> 248 | E20: ='الوارد بعد الجرد'!AC20 -> 0 | F20: =C20-D20+E20 -> 1000 | G20: 4 | H20: =G20*F20 -> 4000 | I20: 200 | K20: =I20*4 -> 800 | L20: =F20-K20 -> 200
A21: 2 | B21: هل انا مدمن | D21: ='الصادر بعد الجرد'!Y21 -> 500 | E21: ='الوارد بعد الجرد'!AC21 -> 500 | F21: =C21-D21+E21 -> 0 | G21: 4 | H21: =G21*F21 -> 0 | I21: 63 | K21: =I21*4 -> 252 | L21: =F21-K21 -> -252
A22: 3 | B22: مرحبا بك فى زمالة م.م. | C22: 100 | D22: ='الصادر بعد الجرد'!Y22 -> 100 | E22: ='الوارد بعد الجرد'!AC22 -> 0 | F22: =C22-D22+E22 -> 0 | G22: 4 | H22: =G22*F22 -> 0 | I22: 63 | K22: =I22*4 -> 252 | L22: =F22-K22 -> -252
A23: 4 | B23: لليوم فقط | C23: 1426 | D23: ='الصادر بعد الجرد'!Y23 -> 0 | E23: ='الوارد بعد الجرد'!AC23 -> 0 | F23: 1726 | G23: 4 | H23: =G23*F23 -> 6904 | I23: 10 | K23: =I23*4 -> 40 | L23: =F23-K23 -> 1686
A24: 5 | B24: التوجية | C24: 401 | D24: ='الصادر بعد الجرد'!Y24 -> 500 | E24: ='الوارد بعد الجرد'!AC24 -> 500 | F24: =C24-D24+E24 -> 401 | G24: 4 | H24: =G24*F24 -> 1604 | I24: 102 | K24: =I24*4 -> 408 | L24: =F24-K24 -> -7
A25: 6 | B25: نظرة أخرى | C25: 2124 | D25: ='الصادر بعد الجرد'!Y25 -> 0 | E25: ='الوارد بعد الجرد'!AC25 -> 0 | F25: =C25-D25+E25 -> 2124 | G25: 4 | H25: =G25*F25 -> 8496 | I25: 2 | K25: =I25*4 -> 8 | L25: =F25-K25 -> 2116
A26: 7 | B26: التعافى والانتكاس | C26: 967 | D26: ='الصادر بعد الجرد'!Y26 -> 0 | E26: ='الوارد بعد الجرد'!AC26 -> 0 | F26: =C26-D26+E26 -> 967 | G26: 4 | H26: =G26*F26 -> 3868 | I26: 11 | K26: =I26*4 -> 44 | L26: =F26-K26 -> 923
A27: 8 | B27: تقبل الذات | C27: 529 | D27: ='الصادر بعد الجرد'!Y27 -> 0 | E27: ='الوارد بعد الجرد'!AC27 -> 0 | F27: =C27-D27+E27 -> 529 | G27: 4 | H27: =G27*F27 -> 2116 | I27: 12 | K27: =I27*4 -> 48 | L27: =F27-K27 -> 481
A28: 9 | B28: مثلث الهاجس الذاتي | C28: 400 | D28: ='الصادر بعد الجرد'!Y28 -> 0 | E28: ='الوارد بعد الجرد'!AC28 -> 0 | F28: =C28-D28+E28 -> 400 | G28: 4 | H28: =G28*F28 -> 1600 | I28: 5 | K28: =I28*4 -> 20 | L28: =F28-K28 -> 380
A29: 10 | B29: مقدمة لاجتماعات زمالة م.م | C29: 3100 | D29: ='الصادر بعد الجرد'!Y29 -> 0 | E29: ='الوارد بعد الجرد'!AC29 -> 0 | F29: =C29-D29+E29 -> 3100 | G29: 4 | H29: =G29*F29 -> 12400 | I29: 10 | K29: =I29*4 -> 40 | L29: =F29-K29 -> 3060
A30: 11 | B30: من - ماذا - كيف ولماذا | C30: 375 | D30: ='الصادر بعد الجرد'!Y30 -> 0 | E30: ='الوارد بعد الجرد'!AC30 -> 0 | F30: =C30-D30+E30 -> 375 | G30: 4 | H30: =G30*F30 -> 1500 | I30: 5 | K30: =I30*4 -> 20 | L30: =F30-K30 -> 355
A31: 12 | B31: تجربة مدمن مع التقبل والإيمان والالتزام | C31: 850 | D31: ='الصادر بعد الجرد'!Y31 -> 0 | E31: ='الوارد بعد الجرد'!AC31 -> 0 | F31: =C31-D31+E31 -> 850 | G31: 4 | H31: =G31*F31 -> 3400 | I31: 4 | K31: =I31*4 -> 16 | L31: =F31-K31 -> 834
A32: 13 | B32: البقاء ممتنعا في الخارج | C32: 345 | D32: ='الصادر بعد الجرد'!Y32 -> 0 | E32: ='الوارد بعد الجرد'!AC32 -> 0 | F32: =C32-D32+E32 -> 345 | G32: 4 | H32: =G32*F32 -> 1380 | I32: 1 | K32: =I32*4 -> 4 | L32: =F32-K32 -> 341
A33: 14 | B33: رسالة لمن هم بالمصحات | C33: 575 | D33: ='الصادر بعد الجرد'!Y33 -> 0 | E33: ='الوارد بعد الجرد'!AC33 -> 0 | F33: =C33-D33+E33 -> 575 | G33: 4 | H33: =G33*F33 -> 2300 | I33: 1 | K33: =I33*4 -> 4 | L33: =F33-K33 -> 571
A34: 15 | B34: التواصل الاجتماعى | C34: 200 | D34: ='الصادر بعد الجرد'!Y34 -> 0 | E34: ='الوارد بعد الجرد'!AC34 -> 0 | F34: =C34-D34+E34 -> 200 | G34: 4 | H34: =G34*F34 -> 800 | I34: 1 | K34: =I34*4 -> 4 | L34: =F34-K34 -> 196
A35: 16 | B35: الخدم الموثوق بهم | C35: 390 | D35: ='الصادر بعد الجرد'!Y35 -> 0 | E35: ='الوارد بعد الجرد'!AC35 -> 0 | F35: =C35-D35+E35 -> 390 | G35: 4 | H35: =G35*F35 -> 1560 | I35: 1 | K35: =I35*4 -> 4 | L35: =F35-K35 -> 386
... A43: 24 | B43: للآباء أو أولياء أمور المدمنين الشباب | C43: 100 | D43: ='الصادر بعد الجرد'!Y43 -> 0 | E43: ='الوارد بعد الجرد'!AC43 -> 0 | F43: =C43-D43+E43 -> 100 | G43: 4 | H43: =G43*F43 -> 400 | I43: 1 | K43: =I43*4 -> 4 | L43: =F43-K43 -> 96
A44: 25 | B44: امكانية الوصول لذوي الاحتيجات | C44: 380 | D44: ='الصادر بعد الجرد'!Y44 -> 0 | E44: ='الوارد بعد الجرد'!AC44 -> 0 | F44: =C44-D44+E44 -> 380 | G44: 4 | H44: =G44*F44 -> 1520 | K44: =I44*4 -> 0 | L44: =F44-K44 -> 380
B46: الشيبات Chips
A47: 1 | B47: Welcome / White | C47: 0 | D47: ='الصادر بعد الجرد'!Y47 -> 0 | E47: ='الوارد بعد الجرد'!AC47 -> 0 | F47: =C47-D47+E47 -> 0 | G47: 20 | H47: =G47*F47 -> 0 | I47: 251 | K47: =I47*4 -> 1004 | L47: =F47-K47 -> -1004
A48: 2 | B48: 30 Days / Orange | C48: 906 | D48: ='الصادر بعد الجرد'!Y48 -> 200 | E48: ='الوارد بعد الجرد'!AC48 -> 0 | F48: =C48-D48+E48 -> 706 | G48: 20 | H48: =G48*F48 -> 14120 | I48: 116 | K48: =I48*4 -> 464 | L48: =F48-K48 -> 242
A49: 3 | B49: 60 Days / Green | C49: 865 | D49: ='الصادر بعد الجرد'!Y49 -> 200 | E49: ='الوارد بعد الجرد'!AC49 -> 0 | F49: =C49-D49+E49 -> 665 | G49: 20 | H49: =G49*F49 -> 13300 | I49: 132 | K49: =I49*4 -> 528 | L49: =F49-K49 -> 137
A50: 4 | B50: 90 Days / Red | C50: 571 | D50: ='الصادر بعد الجرد'!Y50 -> 200 | E50: ='الوارد بعد الجرد'!AC50 -> 0 | F50: =C50-D50+E50 -> 371 | G50: 20 | H50: =G50*F50 -> 7420 | I50: 167 | K50: =I50*4 -> 668 | L50: =F50-K50 -> -297
...

Sheet الصادر بعد الجرد
A1: البند | E1: lit comt | F1: lit comt | G1: lit comt | H1: lit comt | I1: lit comt | J1: karnaval upper egypt | K1: Lit comt | L1: lit comt | M1: Lit Comt | N1: lit comt | O1: Lit Comt | Y1: إجمالي الصادر
A2: التاريخ | E2: 46362 | F2: 31-7/2026
B3: code | C3: book in english | D3: الكتب
A4: 1 | D4: النص الاساسى | E4: 150 | Y4: =SUM(E4:X4) -> 150
A5: 2 | D5: إنه يعمل - كيف ولماذا | E5: 50 | Y5: =SUM(E5:X5) -> 50
A6: 3 | D6: دليل العمل بالخطوات | E6: 150 | Y6: =SUM(E6:X6) -> 150
A7: 4 | D7: كتاب لليوم فقط | E7: 40 | Y7: =SUM(E7:X7) -> 40
A8: 5 | D8: الدليل التمهيدى | Y8: =SUM(E8:X8) -> 0
A9: 6 | D9: روح تقاليدنا | E9: 40 | Y9: =SUM(E9:X9) -> 40
A10: 7 | D10: living clean | E10: 60 | Y10: =SUM(E10:X10) -> 60
A11: 8 | D11: النص الاساسى (جيب) | Y11: =SUM(E11:X11) -> 0
A12: 9 | D12: إنة يعمل - كيف ولماذا (جيب) | Y12: =SUM(E12:X12) -> 0
A13: 10 | D13: دليل العمل بالخطوات (جيب) | Y13: =SUM(E13:X13) -> 0
A14: 11 | D14: كتاب لليوم فقط (جيب) | Y14: =SUM(E14:X14) -> 0
A15: 12 | D15: النص الاساسى (تذكاري) | Y15: =SUM(E15:X15) -> 0
A16: 13 | D16: أنة يعمل - كيف ولماذا (تذكاري) | Y16: =SUM(E16:X16) -> 0
A17: 14 | D17: دليل عمل الخطوات (تذكاري) | Y17: =SUM(E17:X17) -> 0
A18: 15 | D18: كتاب لليوم فقط (تذكاري) | Y18: =SUM(E18:X18) -> 0
B19: code | C19: IP in english | D19: الكتيبات (IP) | Y19: =SUM(E19:X19) -> 0
A20: 1 | D20: للعضو الجديد | E20: 248 | Y20: =SUM(E20:X20) -> 248
A21: 2 | D21: هل انا مدمن | E21: 500 | Y21: =SUM(E21:X21) -> 500
A22: 3 | D22: مرحبا بك فى زمالة م.م. | F22: 100 | Y22: =SUM(E22:X22) -> 100 | AA22: 2927
A23: 4 | D23: لليوم فقط | Y23: =SUM(E23:X23) -> 0 | AA23: =AA22-Y23 -> 2927
A24: 5 | D24: التوجية | E24: 500 | Y24: =SUM(E24:X24) -> 500 | Z24: there was 300 ip delivered at october to lit sub comt so I add them at november
A25: 6 | D25: نظرة أخرى | Y25: =SUM(E25:X25) -> 0
A26: 7 | D26: التعافى والانتكاس | Y26: =SUM(E26:X26) -> 0
A27: 8 | D27: تقبل الذات | Y27: =SUM(E27:X27) -> 0
A28: 9 | D28: مثلث الهاجس الذاتي | Y28: =SUM(E28:X28) -> 0
A29: 10 | D29: مقدمة لاجتماعات زمالة م.م | Y29: =SUM(E29:X29) -> 0
A30: 11 | D30: من - ماذا - كيف ولماذا | Y30: =SUM(E30:X30) -> 0
A31: 12 | D31: تجربة مدمن مع التقبل والإيمان والالتزام | Y31: =SUM(E31:X31) -> 0
A32: 13 | D32: البقاء ممتنعا في الخارج | Y32: =SUM(E32:X32) -> 0
A33: 14 | D33: رسالة لمن هم بالمصحات | Y33: =SUM(E33:X33) -> 0
A34: 15 | D34: التواصل الاجتماعى | Y34: =SUM(E34:X34) -> 0
A35: 16 | D35: الخدم الموثوق بهم | Y35: =SUM(E35:X35) -> 0
A36: 17 | D36: الامور المالية | Y36: =SUM(E36:X36) -> 0
... A38: 19 | D38: السلوك المعيق | Y38: =SUM(E38:X38) -> 0
A39: 20 | D39: المجموعة | E39: 500 | Y39: =SUM(E39:X39) -> 500
A40: 21 | D40: معايشة البرنامج | Y40: =SUM(E40:X40) -> 0
A41: 22 | D41: المنعزل - البقاء ممتنعاً في الخارج | Y41: =SUM(E41:X41) -> 0
...

Sheet Inventory 12-6-2026
A11: الكتب | C11: الرصيد الحالي | D11: Count | E11: differnce | F11: Remarks
A12: 1 | B12: النص الاساسى | C12: 255 | D12: 255 | E12: =D12-C12 -> 0
A13: 2 | B13: إنه يعمل - كيف ولماذا | C13: 355 | D13: 355 | E13: =D13-C13 -> 0
A14: 3 | B14: دليل العمل بالخطوات | C14: 50 | D14: 100 | E14: =D14-C14 -> 50 | F14: there is wrong input when we received it 24/1/2026
A15: 4 | B15: كتاب لليوم فقط | C15: 525 | D15: 525 | E15: =D15-C15 -> 0
A16: 5 | B16: الدليل التمهيدى | C16: 377 | D16: 377 | E16: =D16-C16 -> 0
A17: 6 | B17: روح تقاليدنا | C17: 907 | D17: 907 | E17: =D17-C17 -> 0
A18: 7 | B18: living clean | C18: 940 | D18: 940 | E18: =D18-C18 -> 0
A19: 8 | B19: النص الاساسى (جيب) | C19: 0 | E19: =D19-C19 -> 0
A20: 9 | B20: إنة يعمل - كيف ولماذا (جيب) | C20: 0 | E20: =D20-C20 -> 0
A21: 10 | B21: دليل العمل بالخطوات (جيب) | C21: 0 | E21: =D21-C21 -> 0
A22: 11 | B22: كتاب لليوم فقط (جيب) | C22: 0 | E22: =D22-C22 -> 0
A23: 12 | B23: النص الاساسى (تذكاري) | C23: 0 | E23: =D23-C23 -> 0
A24: 13 | B24: أنة يعمل - كيف ولماذا (تذكاري) | C24: 4 | D24: 4 | E24: =D24-C24 -> 0
A25: 14 | B25: دليل عمل الخطوات (تذكاري) | C25: 4 | D25: 4 | E25: =D25-C25 -> 0 | F25: need to be trough as old printing
A26: 15 | B26: كتاب لليوم فقط (تذكاري) | C26: 0 | E26: =D26-C26 -> 0
B27: الكتيبات (IP) | E27: =D27-C27 -> 0
A28: 1 | B28: للعضو الجديد | C28: 1248 | D28: 1248 | E28: =D28-C28 -> 0
A29: 2 | B29: هل انا مدمن | C29: 0 | E29: =D29-C29 -> 0
A30: 3 | B30: مرحبا بك فى زمالة م.م. | C30: 100 | D30: 100 | E30: =D30-C30 -> 0
A31: 4 | B31: لليوم فقط | C31: 1427 | D31: 1426 | E31: =D31-C31 -> -1 | F31: input wrong Lit didn’t receive 300 written wrong at paper of receiving no this number
A32: 5 | B32: التوجية | C32: 401 | D32: 401 | E32: =D32-C32 -> 0
A33: 6 | B33: نظرة أخرى | C33: 2124 | D33: 2124 | E33: =D33-C33 -> 0
A34: 7 | B34: التعافى والانتكاس | C34: 967 | D34: 967 | E34: =D34-C34 -> 0
A35: 8 | B35: تقبل الذات | C35: 529 | D35: 529 | E35: =D35-C35 -> 0
A36: 9 | B36: مثلث الهاجس الذاتي | C36: 405 | D36: 400 | E36: =D36-C36 -> -5
A37: 10 | B37: مقدمة لاجتماعات زمالة م.م | C37: -100 | D37: 3100 | E37: =D37-C37 -> 3200 | F37: need to burn as wrong
A38: 11 | B38: من - ماذا - كيف ولماذا | C38: 375 | D38: 375 | E38: =D38-C38 -> 0
A39: 12 | B39: تجربة مدمن مع التقبل والإيمان والالتزام | C39: 850 | D39: 850 | E39: =D39-C39 -> 0
A40: 13 | B40: البقاء ممتنعا في الخارج | C40: 325 | D40: 345 | E40: =D40-C40 -> 20
A41: 14 | B41: رسالة لمن هم بالمصحات | C41: 575 | D41: 575 | E41: =D41-C41 -> 0
A42: 15 | B42: التواصل الاجتماعى | C42: 200 | D42: 200 | E42: =D42-C42 -> 0
A43: 16 | B43: الخدم الموثوق بهم | C43: 390 | D43: 390 | E43: =D43-C43 -> 0
A44: 17 | B44: الامور المالية | C44: 350 | D44: 350 | E44: =D44-C44 -> 0
A45: 18 | B45: تمويل الخدمات | C45: 490 | D45: 490 | E45: =D45-C45 -> 0
A46: 19 | B46: السلوك المعيق | C46: 1246 | D46: 1245 | E46: =D46-C46 -> -1
A47: 20 | B47: المجموعة | C47: 0 | D47: 0 | E47: =D47-C47 -> 0
A48: 21 | B48: معايشة البرنامج | C48: 270 | D48: 270 | E48: =D48-C48 -> 0
A49: 22 | B49: المنعزل - البقاء ممتنعاً | C49: 294 | D49: 294 | E49: =D49-C49 -> 0
... A52: 25 | B52: امكانية الوصول لذوي الاحتيجات | C52: 380 | D52: 380 | E52: =D52-C52 -> 0
...

Sheet الوارد بعد الجرد
A1: البند | E1: Lit Comt | AC1: إجمالي الوارد
A2: التاريخ | E2: 46362
B3: code | C3: book in english | D3: الكتب
A4: 1 | D4: النص الاساسى | E4: 100 | AC4: =SUM(E4:AB4) -> 100
A5: 2 | D5: إنه يعمل - كيف ولماذا | AC5: =SUM(E5:AB5) -> 0
A6: 3 | D6: دليل العمل بالخطوات | E6: 150 | AC6: =SUM(E6:AB6) -> 150
A7: 4 | D7: كتاب لليوم فقط | AC7: =SUM(E7:AB7) -> 0
A8: 5 | D8: الدليل التمهيدى | AC8: =SUM(E8:AB8) -> 0
A9: 6 | D9: روح تقاليدنا | AC9: =SUM(E9:AB9) -> 0
A10: 7 | D10: living clean arabic | AC10: =SUM(E10:AB10) -> 0
A11: 8 | D11: النص الاساسى (جيب) | AC11: =SUM(E11:AB11) -> 0
A12: 9 | D12: إنة يعمل - كيف ولماذا (جيب) | AC12: =SUM(E12:AB12) -> 0
A13: 10 | D13: دليل العمل بالخطوات (جيب) | AC13: =SUM(E13:AB13) -> 0
A14: 11 | D14: كتاب لليوم فقط (جيب) | AC14: =SUM(E14:AB14) -> 0
A15: 12 | D15: النص الاساسى (تذكاري) | AC15: =SUM(E15:AB15) -> 0
A16: 13 | D16: أنة يعمل - كيف ولماذا (تذكاري) | AC16: =SUM(E16:AB16) -> 0
A17: 14 | D17: دليل عمل الخطوات (تذكاري) | AC17: =SUM(E17:AB17) -> 0
A18: 15 | D18: كتاب لليوم فقط (تذكاري) | AC18: =SUM(E18:AB18) -> 0
B19: code | C19: IP | D19: الكتيبات (IP) | AC19: =SUM(E19:AB19) -> 0
A20: 1 | D20: للعضو الجديد | AC20: =SUM(E20:AB20) -> 0
A21: 2 | D21: هل انا مدمن | E21: 500 | AC21: =SUM(E21:AB21) -> 500
A22: 3 | D22: مرحبا بك فى زمالة م.م. | AC22: =SUM(E22:AB22) -> 0
A23: 4 | D23: لليوم فقط | AC23: =SUM(E23:AB23) -> 0
A24: 5 | D24: التوجية | E24: 500 | AC24: =SUM(E24:AB24) -> 500 | AD24: there was 300 ip delivered at october to lit sub comt so I add them at november
A25: 6 | D25: نظرة أخرى | AC25: =SUM(E25:AB25) -> 0
A26: 7 | D26: التعافى والانتكاس | AC26: =SUM(E26:AB26) -> 0
A27: 8 | D27: تقبل الذات | AC27: =SUM(E27:AB27) -> 0
A28: 9 | D28: مثلث الهاجس الذاتي | AC28: =SUM(E28:AB28) -> 0
A29: 10 | D29: مقدمة لاجتماعات زمالة م.م | AC29: =SUM(E29:AB29) -> 0
A30: 11 | D30: من - ماذا - كيف ولماذا | AC30: =SUM(E30:AB30) -> 0
A31: 12 | D31: تجربة مدمن مع التقبل والإيمان والالتزام | AC31: =SUM(E31:AB31) -> 0
A32: 13 | D32: البقاء ممتنعا في الخارج | AC32: =SUM(E32:AB32) -> 0
A33: 14 | D33: رسالة لمن هم بالمصحات | AC33: =SUM(E33:AB33) -> 0
A34: 15 | D34: التواصل الاجتماعى | AC34: =SUM(E34:AB34) -> 0
A35: 16 | D35: الخدم الموثوق بهم | AC35: =SUM(E35:AB35) -> 0
A36: 17 | D36: الامور المالية | AC36: =SUM(E36:AB36) -> 0
... A38: 19 | D38: السلوك المعيق | AC38: =SUM(E38:AB38) -> 0
A39: 20 | D39: المجموعة | E39: 500 | AC39: =SUM(E39:AB39) -> 500
A40: 21 | D40: معايشة البرنامج | AC40: =SUM(E40:AB40) -> 0
A41: 22 | D41: المنعزل - البقاء ممتنعاً في الخارج | AC41: =SUM(E41:AB41) -> 0
...

Sheet order received from WSO us 2024
A1: orders Febauary March April 2024 | C1: from WSO USA to Egypt | D1: Order 1
A2: description | C2: order pack | D2: from | E2: Received after Egyptian tax | F2: price/us$ | G2: price after discount/us$ | H2: Owing balance for WSO/US$ | I2: Differnce not received | L2: Received at Sofia 2024
A3: البيان | C3: الطلبية/من مكتب الخدمة العالمي | D3: من | E3: المستلم بعد الجمرك | F3: السعر/دولار امريكي | G3: نسبة الخصم ٥٠٪ | H3: سوف يتم دفعه الي مكتب الخدمة العالمي | I3: فرق المرسل/المستلم | L3: order to be delivered at sofia | M3: Code | N3: Descraption | O3: order | P3: from
A4: 1 | B4: Welcome / White | C4: =300+150+150 -> 600 | D4: WSO | E4: =148+147+146+147 -> 588 | F4: 0.4 | G4: =F4/2 -> 0.2 | H4: =G4*E4 -> 117.6 | I4: =E4-C4 -> -12 | L4: 1 | M4: 9603 | N4: sponsorship medallion & keychain | O4: 10 | P4: wso
A5: 2 | B5: 30 Days / Orange | C5: =300+150+150 -> 600 | D5: WSO | E5: =148+147+148+147 -> 590 | F5: 0.4 | G5: =F5/2 -> 0.2 | H5: =G5*E5 -> 118 | I5: =E5-C5 -> -10 | L5: 2 | M5: 9054 | N5: literature rack (wire 16 pocket) | O5: 1 | P5: wso
A6: 3 | B6: 60 Days / Green | C6: =300+150+150 -> 600 | D6: WSO | E6: =148+146+148+148 -> 590 | F6: 0.4 | G6: =F6/2 -> 0.2 | H6: =G6*E6 -> 118 | I6: =E6-C6 -> -10 | L6: 3 | M6: 6200 | N6: 1 year triplate ( purple/dark blue/black | O6: 2 | P6: wso
A7: 4 | B7: 90 Days / Red | C7: =300+150+150 -> 600 | D7: WSO | E7: =148+147+147+147 -> 589 | F7: 0.4 | G7: =F7/2 -> 0.2 | H7: =G7*E7 -> 117.8 | I7: =E7-C7 -> -11 | L7: 4 | M7: 6200 | N7: 4 years triplate | O7: 2 | P7: wso
A8: 5 | B8: 6 Months / Blue | C8: =300+150+150 -> 600 | D8: WSO | E8: =146+145+145+145 -> 581 | F8: 0.4 | G8: =F8/2 -> 0.2 | H8: =G8*E8 -> 116.2 | I8: =E8-C8 -> -19 | L8: 5 | M8: 6300 | N8: 10 years triplate | O8: 2 | P8: wso
A9: 6 | B9: 9 Months / Yellow | C9: =150+150+150 -> 450 | D9: WSO | E9: =145+145+145 -> 435 | F9: 0.4 | G9: =F9/2 -> 0.2 | H9: =G9*E9 -> 87 | I9: =E9-C9 -> -15 | L9: 6 | M9: 6300 | N9: etirnity triplate medallion | O9: 4 | P9: wso
A10: 7 | B10: 1 Year / Moonglow | C10: =150+150+150 -> 450 | D10: WSO | E10: =141+142+141 -> 424 | F10: 0.4 | G10: =F10/2 -> 0.2 | H10: =G10*E10 -> 84.8 | I10: =E10-C10 -> -26 | L10: 7 | M10: 6200 | N10: etirnity triplate medallion | O10: 3 | P10: wso
A11: 8 | B11: 18 Months / Grey | C11: =150+100 -> 250 | D11: WSO | E11: =149+99 -> 248 | F11: 0.4 | G11: =F11/2 -> 0.2 | H11: =G11*E11 -> 49.6 | I11: =E11-C11 -> -2 | L11: 8 | M11: GOLD | N11: etirnity triplate medallion | P11: wso
A12: 9 | B12: Multiple Years / Black | C12: =150+150+150 -> 450 | D12: WSO | E12: =146+147+147 -> 440 | F12: 0.4 | G12: =F12/2 -> 0.2 | H12: =G12*E12 -> 88 | I12: =E12-C12 -> -10 | L12: 9 | M12: 6800 | N12: etirnity triplate medallion | O12: 2 | P12: wso
A13: 10 | B13: SET OF ENGLISH READING | C13: 5 | D13: WSO | E13: 5 | F13: 1 | G13: =F13/2 -> 0.5 | H13: =G13*E13 -> 2.5 | I13: =E13-C13 -> 0 | L13: 10 | M13: 6090 | N13: keychain for etched medallion silver | O13: 5 | P13: wso
A14: 11 | B14: It Works: How and Why (Hard Cover) | C14: 2 | D14: WSO | E14: 2 | F14: 10.7 | G14: =F14/2 -> 5.35 | H14: =G14*E14 -> 10.7 | I14: =E14-C14 -> 0 | L14: 11 | M14: 6091 | N14: keychain for bronze- black | O14: 10 | P14: wso
A15: 12 | B15: Step Working Guide | C15: 5 | D15: WSO | E15: 5 | F15: 10.1 | G15: =F15/2 -> 5.05 | H15: =G15*E15 -> 25.25 | I15: =E15-C15 -> 0 | L15: 12 | M15: 6092 | N15: keychain for bronze- satin gold | O15: 10 | P15: wso
A16: 13 | B16: Large-Print It Works: How and Why | C16: 3 | D16: WSO | E16: 3 | F16: 10.7 | G16: =F16/2 -> 5.35 | H16: =G16*E16 -> 16.05 | I16: =E16-C16 -> 0 | L16: 13 | M16: 6903 | N16: keychain for bronze - bronze | O16: 10 | P16: wso
A17: 14 | B17: An Introductory Guide to NA | C17: 20 | D17: WSO | E17: 20 | F17: 2.1 | G17: =F17/2 -> 1.05 | H17: =G17*E17 -> 21 | I17: =E17-C17 -> 0
A18: Total | H18: =SUM(H4:H17) -> 972.5 | I18: =SUM(I4:I17) -> -115
A20: Order may June July 2024 | C20: from WSO USA to Egypt | D20: Orderv 2
B21: descraption | D21: order QTY | E21: Received after Egypatain tax | F21: price/us$ | I21: Differnce not received
A22: البيان | C22: الطلبية/من مكتب الخدمة العالمي | D22: من | E22: المستلم بعد الجمرك | F22: فرق المرسل/المستلم | I22: فرق المرسل/المستلم
A23: 1 | B23: Welcome / White | C23: chip | D23: 500 | E23: 493 | F23: =E23-D23 -> -7 | I23: =E23-D23 -> -7
A24: 2 | B24: 30 Days / Orange | C24: chip | D24: 500 | E24: 479 | F24: =E24-D24 -> -21 | I24: =E24-D24 -> -21
A25: 3 | B25: 60 Days / Green | C25: chip | D25: 500 | E25: 490 | F25: =E25-D25 -> -10 | I25: =E25-D25 -> -10
A26: 4 | B26: 90 Days / Red | C26: chip | D26: 1000 | E26: 969 | F26: =E26-D26 -> -31 | I26: =E26-D26 -> -31
A27: 5 | B27: 6 Months / Blue | C27: chip | D27: 250 | E27: 240 | F27: =E27-D27 -> -10 | I27: =E27-D27 -> -10
A28: 6 | B28: 9 Months / Yellow | C28: chip | D28: 450 | E28: 432 | F28: =E28-D28 -> -18 | I28: =E28-D28 -> -18
A29: 7 | B29: 1 Year / Moonglow | C29: chip | D29: 200 | E29: 193 | F29: =E29-D29 -> -7 | I29: =E29-D29 -> -7
A30: 8 | B30: 18 Months / Grey | C30: chip | D30: 200 | E30: 194 | F30: =E30-D30 -> -6 | I30: =E30-D30 -> -6
A31: 9 | B31: Muiltple Years / Black | C31: chip | D31: 206 | E31: 202 | F31: =E31-D31 -> -4 | I31: =E31-D31 -> -4
A32: 10 | B32: Basic Text - Reg Size | C32: book | D32: 10 | E32: 10 | F32: =E32-D32 -> 0 | I32: =E32-D32 -> 0
A33: 11 | B33: Step Working Guide | C33: book | D33: 15 | E33: 15 | F33: =E33-D33 -> 0 | I33: =E33-D33 -> 0
A34: 12 | B34: مجموعة قراءات (عربي) | C34: arabic reading | D34: 19 | E34: 19 | F34: =E34-D34 -> 0 | I34: =E34-D34 -> 0
A35: Total | I35: =SUM(I23:I34) -> -114
J47: Total
